Workbook

Sheet _SUM
H1: CÔNG TY CỔ PHẦN TẬP ĐOÀN TDI
H2: TDI GROUP JOINT STOCK COMPANY
H3: A16-NV6, ô số 10, KĐT mới đường Lê Trọng Tấn, An Khánh, Hoài Đức, HN
H4: Tel: (024) 7308.6632 - info@tdigroup.vn - www.tdigroup.vn
A6: BẢNG TỔNG HỢP DỰ TOÁN
B7: HSKL | C7: HSVL | D7: HCTB | E7: HSNC | F7: HS chung | G7: LÀM TRÒN
B8: 1 | C8: 1.25 | D8: 1.1 | E8: 1.15 | F8: 1 | G8: -2
B9: Loại VL | C9: Hệ số | E9: Loại VL | F9: Hệ số
C10: VL | D10: NC | F10: VL | G10: NC
B11: Cáp điện | C11: 1 | D11: 1 | E11: PK Ống PVC | F11: 1 | G11: 1
B12: Ống luồn dây | C12: 1 | D12: 1 | E12: Ống PVC | F12: 1 | G12: 1
B13: Thang cáp | C13: 1 | D13: 1 | E13: Ống PPR | F13: 1 | G13: 1
B14: Phụ kiện T.cáp | C14: 1 | D14: 1 | E14: PK Ống PPR | F14: 1 | G14: 1
B15: Máng cáp | C15: 1 | D15: 1 | E15: Ống HDPE | F15: 1 | G15: 1
B16: Phụ kiện M.cáp | C16: 1 | D16: 1 | E16: PK HDPE | F16: 1 | G16: 1
B17: Ống thép | C17: 1 | D17: 1 | E17: Ống gió | F17: 1 | G17: 1
B18: PK ống thép | C18: 1 | D18: 1 | E18: PK Ống gió | F18: 1 | G18: 1
B19: Van Khóa Thép | C19: 1 | D19: 1 | E19: Cửa gió | F19: 1 | G19: 1
B20: Công tác khác | C20: 1 | D20: 1 | E20: Van gió | F20: 1 | G20: 1
B21: Ống đồng | C21: 1 | D21: 1 | E21: Bảo ôn | F21: 1 | G21: 1
B22: Thiết bị Điện | C22: 1 | D22: 1 | E22: Quạt thông gió | F22: 1 | G22: 1
... B24: Điều Hoà | C24: 1 | D24: 1 | E24: Thiết bị báo cháy | F24: 1 | G24: 1
E25: Hầm (2 hầm) | F25: =4690*2 | G25: Tổn diện tích | H25: =SUM(F25:F30)
E26: TTTM 1-3 (3 tâng) | F26: =2520*3 | G26: Đơn giá/m2 | H26: =G57/H25
E27: KS 4-8 (5 tầng) | F27: =2220*5 | G27: Vật tư/m2 | H27: =SUBTOTAL(9,E39:E50)/H25
E28: CT1 9-25 (17 tầng) | F28: =1080*17 | G28: Nhân công/m2 | H28: =SUBTOTAL(9,F39:F50)/H25
E29: CT2 9-25 (17 tầng) | F29: =1020*17
E30: Mái + sần vườn | F30: =600+250+285
A32: Dự án: TGC (CT07) - Nhà ở chung cư & kết hợp thương mại | G32: Số: | H32: BG/TDI-PDT/TDI23417
A33: Hạng mục: Cung cấp & lắp đặt hệ thống cơ điện | G33: Ngày: | H33: =TODAY()
A34: STT | B34: Hạng Mục Công Việc | C34: Đơn Vị | D34: KL | E34: Đơn Giá | G34: Thành Tiền | H34: Ghi Chú
E35: Vật Tư | F35: Nhân Công
B38: CHI PHÍ TRỰC TIẾP | G38: =SUM(G39,G45)
A39: A | B39: SERVICE | C39: Hệ | D39: 1 | E39: =+'B2_SERVICE '!AZ1759 | F39: =+'B2_SERVICE '!BA1759 | G39: =+'B2_SERVICE '!BB1759
A45: B | B45: FITTING | C45: Hệ | D45: 1 | E45: =+B3_Fittings!AZ323 | F45: =+B3_Fittings!BA323 | G45: =+B3_Fittings!BB323
B51: CHI PHÍ GIÁN TIẾP | G51: =SUBTOTAL(9,G52:G56)
B52: Chi Phí Văn Phòng, Kho Bãi,… | C52: Lot | D52: 0.01 | G52: =$G$38*D52
B53: Chi phí Quảng Lý Gián Tiếp | C53: Lot | D53: 0.035 | G53: =$G$38*D53
B54: Chi phí tiện ích trong thi công (Điện, Nước, Vận thang, Vận chuyển rác thải ra trong phạm vi công trường.) | C54: Lot | D54: 0.02 | G54: =$G$38*D54
B55: Bảo Hộ, Dụng Cụ An Toàn, Bảo hiểm cho người lao động | C55: Lot | D55: 0.01 | G55: =$G$38*D55
...

Sheet _TPL
BC1: CÔNG TY CỔ PHẦN TẬP ĐOÀN TDI
BC2: TDI GROUP JOINT STOCK COMPANY
BC3: =Summary!H3
BC4: Tel: (024) 7308.6632 - info@tdigroup.vn - www.tdigroup.vn
A5: CHI TIẾT GIÁ
A6: =Summary!A32 | BB6: =Summary!G32 | BC6: =Summary!H32
A7: Hạng mục: Hệ thống Điện Động Lực | AN7: VTP MFĐ | AO7: VTP Thiết bị | AP7: VTP OLD | AQ7: VTP TMC | AR7: VTP cáp điện | AS7: VTP ống nước | AT7: VTP Bảo ôn | AU7: VTP OG | AV7: VTP CSTĐ | AW7: CP testing | AX7: CP testing Điều hòa | AY7: VTP ống đồng | AZ7: Phụ kiện bơm | BA7: Phụ kiện TMC | BB7: =Summary!G33 | BC7: =Summary!H33
O8: HS hao hụt | P8: HSVL | Q8: HSNC | R8: HSTB | T8: HSKL | AN8: 0.03 | AO8: 0.01 | AP8: 0.05 | AQ8: 0.12 | AR8: 0.015 | AS8: 0.1 | AT8: 0.07 | AU8: 0.12 | AV8: 0.03 | AW8: 0.002 | AX8: 0.01 | AY8: 0.03 | AZ8: 0.04 | BA8: 0.15 | BB8: HS chung | BC8: LÀM TRÒN
O9: 1.02 | P9: =Summary!C8 | Q9: =Summary!E8 | R9: =Summary!D8 | T9: 1 | BB9: =Summary!F8 | BC9: =Summary!G8
A10: STT | B10: Hạng mục công việc | C10: Thông số kỹ thuật | D10: Mã hiệu | E10: Nhãn hiệu | F10: Xuất xứ | G10: Đơn vị | H10: Quantity/ Khối lượng nt | L10: Nội Dung Công Việc | M10: Quy cách Mã Hiệu | N10: Nhãn Hiệu Xuất Xứ | O10: Đơn Vị | P10: Đơn giá gốc | R10: Bộ lọc | T10: Tổng KL tạm tính | U10: Diễn giải chi tiết KL | AM10: KL | AN10: Đơn giá | AQ10: Basement | AT10: BLOCK A | AW10: BLOCK B | AZ10: Total | BC10: Ghi Chú
H11: Basement | I11: BLOCK A | J11: BLOCK B | K11: Tổng khối lượng | P11: Vật liệu | Q11: Nhân Công | R11: Chủng loại | S11: In ấn | U11: Trục chính | W11: Tầng Hầm | Z11: Khối đế phía trên | AC11: Hành lang điển hình | AF11: Căn hộ điển hình | AK11: Khu vực khác | AN11: Vật Liệu | AO11: Nhân công | AP11: ĐG Tổng | AQ11: Amount/ thành tiền | AS11: Total Amount/ Tổng thành tiền | AT11: Amount/ thành tiền | AV11: Total Amount/ Tổng thành tiền | AW11: Amount/ thành tiền | AY11: Total Amount/ Tổng thành tiền | AZ11: Amount/ thành tiền | BB11: Total Amount/ Tổng thành tiền
U12: Trục 1 | V12: Trục 2 | W12: Hầm 1 | X12: Hầm 2 | Y12: Hầm 3 | Z12: Tầng 1 | AA12: Tầng 2 | AB12: Tầng 3 | AC12: HL1 | AD12: HL2 | AE12: HL3 | AF12: CH-01 | AG12: CH-02 | AH12: CH-03 | AI12: CH-04 | AJ12: CH-05 | AK12: Khác 2 | AL12: Khác 2 | AQ12: Supply/ Cung cấp | AR12: Installation/ lắp đặt | AT12: Supply/ Cung cấp | AU12: Installation/ lắp đặt | AW12: Supply/ Cung cấp | AX12: Installation/ lắp đặt | AZ12: Supply/ Cung cấp | BA12: Installation/ lắp đặt
B13: sec0
B14: sec1
B15: sec2
B16: sec3
B17: note
B18: note_bold
B19: item
B20: total
